Workbook

Sheet README
A1: Constructed-four matchup win-rate workbook
A2: Percentages use Wilson 95% confidence intervals. Model-vs-heuristic denominators include crashes/non-won games as non-model wins, matching arms_report.json.
A4: Workbook contents
A5: Sheet | B5: Evaluation | C5: Games | D5: Model/row wins | E5: Decisive | F5: Non-decisive | G5: Overall model win rate | H5: Source
A6: HvH_40000 | B6: Heuristic vs heuristic — 40,000 generated games | C6: 40000 | E6: 40000 | F6: 0 | H6: data/runs/constructed-four-heur-40000-20260909-211341-20260909-211341
A7: BC_initial_8000 | B7: Initial behavior clone vs heuristic — 8,000 games | C7: 8000 | D7: 3248 | E7: 7991 | F7: 9 | G7: 0.406 | H7: data/training/constructed-four-auto-20260909-211341/arms-report.json
A8: RL_iter05 | B8: RL checkpoint after iteration 5 — 4,000 eval games | C8: 4000 | D8: 1749 | E8: 3994 | F8: 6 | G8: 0.43725 | H8: data/training/constructed-four-rl-4000/iter-004/arms-report.json
A9: RL_iter10 | B9: RL checkpoint after iteration 10 — 4,000 eval games | C9: 4000 | D9: 1805 | E9: 3994 | F9: 6 | G9: 0.45125 | H9: data/training/constructed-four-rl-4000/iter-009/arms-report.json
A10: RL_iter15 | B10: RL checkpoint after iteration 15 — 4,000 eval games | C10: 4000 | D10: 1968 | E10: 3994 | F10: 6 | G10: 0.492 | H10: data/training/constructed-four-rl-4000/iter-014/arms-report.json
A11: RL_iter20 | B11: RL checkpoint after iteration 20 — 4,000 eval games | C11: 4000 | D11: 2025 | E11: 3994 | F11: 6 | G11: 0.50625 | H11: data/training/constructed-four-rl-4000/iter-019/arms-report.json
A12: RL_iter30 | B12: RL checkpoint after iteration 30 — 8,000 eval games | C12: 8000 | D12: 4091 | E12: 7993 | F12: 7 | G12: 0.511375 | H12: data/training/constructed-four-rl-4000/iter-029/arms-report.json
A13: RL_iter40 | B13: RL checkpoint after iteration 40 — 8,000 eval games | C13: 8000 | D13: 4051 | E13: 7991 | F13: 9 | G13: 0.506375 | H13: data/training/constructed-four-rl-4000/iter-039/arms-report.json
A14: Interpretation of heuristic-vs-heuristic sheet
A15: Off-diagonal cells pool both seat assignments, so A-vs-B and B-vs-A use the same games with complementary winners. Same-deck diagonal cells use seat-0 wins.
A17: Evaluation timing
A18: The recorded RL configuration has arms_every = 5. Thus iter-004, iter-009, iter-014, iter-019, iter-029, and iter-039 correspond to completed iterations 5, 10, 15, 20, 30, and 40.
A20: RL30_vs_Baselines | B20: Iteration-30 changes versus heuristic-vs-heuristic and initial behavior-clone references. | H20: RL_iter30, HvH_40000, BC_initial_8000
A21: RL40_vs_Baselines | B21: Iteration-40 changes versus heuristic-vs-heuristic and initial behavior-clone references. | H21: RL_iter40, HvH_40000, BC_initial_8000
A22: RL40_vs_RL30 | B22: Direct per-matchup and overall comparison of iteration 40 against iteration 30. | H22: RL_iter40, RL_iter30
A23: All_Matrices_Combined | B23: All four actual matrices with CIs plus all five comparison matrices in one view. | H23: HvH_40000, BC_initial_8000, RL_iter30, RL_iter40, comparison sheets
A24: Comparison cells are percentage-point changes: positive favors the first-named model, negative favors the reference.
A25: All_Matrices_Combined uses source-sheet links, TEXTBEFORE/NUMBERVALUE extraction for comparisons, and formula-driven Wilson CIs.

Sheet HvH_40000
A1: Heuristic vs heuristic — 40,000 generated games
A2: Rows: Row deck; columns: Column deck.
A3: Source: data/runs/constructed-four-heur-40000-20260909-211341-20260909-211341
A4: Off-diagonal cells pool both seat assignments; each game contributes to both directed cells. Diagonal cells report seat-0 win rate for same-deck games. Cell counts therefore need not sum to 40,000.
A6: Win rate with 95% Wilson CI
A7: Row deck \ Column deck | B7: Blue Tempo | C7: Green Stompy | D7: Red Aggro | E7: White Weenie
A8: Blue Tempo | B8: 51.3% [49.3%, 53.2%] | C8: 15.1% [14.1%, 16.1%] | D8: 26.5% [25.2%, 27.7%] | E8: 16.3% [15.3%, 17.4%]
A9: Green Stompy | B9: 84.9% [83.9%, 85.9%] | C9: 50.9% [48.9%, 52.8%] | D9: 66.2% [64.9%, 67.5%] | E9: 51.0% [49.6%, 52.4%]
A10: Red Aggro | B10: 73.5% [72.3%, 74.8%] | C10: 33.8% [32.5%, 35.1%] | D10: 51.6% [49.6%, 53.6%] | E10: 32.2% [31.0%, 33.4%]
A11: White Weenie | B11: 83.7% [82.6%, 84.7%] | C11: 49.0% [47.6%, 50.4%] | D11: 67.8% [66.6%, 69.0%] | E11: 52.8% [50.9%, 54.7%]
A14: Model/row wins
A15: Row deck \ Column deck | B15: Blue Tempo | C15: Green Stompy | D15: Red Aggro | E15: White Weenie
A16: Blue Tempo | B16: 1348 | C16: 739 | D16: 1246 | E16: 801
A17: Green Stompy | B17: 4151 | C17: 1287 | D17: 3191 | E17: 2596
A18: Red Aggro | B18: 3464 | C18: 1629 | D18: 1213 | E18: 1754
A19: White Weenie | B19: 4099 | C19: 2494 | D19: 3696 | E19: 1389
A21: Total games in denominator
A22: Row deck \ Column deck | B22: Blue Tempo | C22: Green Stompy | D22: Red Aggro | E22: White Weenie
A23: Blue Tempo | B23: 2630 | C23: 4890 | D23: 4710 | E23: 4900
A24: Green Stompy | B24: 4890 | C24: 2530 | D24: 4820 | E24: 5090
A25: Red Aggro | B25: 4710 | C25: 4820 | D25: 2350 | E25: 5450
A26: White Weenie | B26: 4900 | C26: 5090 | D26: 5450 | E26: 2630
A28: Decisive games
A29: Row deck \ Column deck | B29: Blue Tempo | C29: Green Stompy | D29: Red Aggro | E29: White Weenie
A30: Blue Tempo | B30: 2630 | C30: 4890 | D30: 4710 | E30: 4900
A31: Green Stompy | B31: 4890 | C31: 2530 | D31: 4820 | E31: 5090
A32: Red Aggro | B32: 4710 | C32: 4820 | D32: 2350 | E32: 5450
A33: White Weenie | B33: 4900 | C33: 5090 | D33: 5450 | E33: 2630
A35: Non-decisive/crash games
A36: Row deck \ Column deck | B36: Blue Tempo | C36: Green Stompy | D36: Red Aggro | E36: White Weenie
A37: Blue Tempo | B37: 0 | C37: 0 | D37: 0 | E37: 0
A38: Green Stompy | B38: 0 | C38: 0 | D38: 0 | E38: 0
A39: Red Aggro | B39: 0 | C39: 0 | D39: 0 | E39: 0
A40: White Weenie | B40: 0 | C40: 0 | D40: 0 | E40: 0
A42: Draw-clock markers
A43: Row deck \ Column deck | B43: Blue Tempo | C43: Green Stompy | D43: Red Aggro | E43: White Weenie
A44: Blue Tempo | B44: 0 | C44: 0 | D44: 0 | E44: 0
A45: Green Stompy | B45: 0 | C45: 15 | D45: 0 | E45: 1
A46: Red Aggro | B46: 0 | C46: 0 | D46: 0 | E46: 0
A47: White Weenie | B47: 0 | C47: 1 | D47: 0 | E47: 2
...

Sheet BC_initial_8000
A1: Initial behavior clone vs heuristic — 8,000 games
A2: Rows: Model deck; columns: Heuristic deck.
A3: Source: data/training/constructed-four-auto-20260909-211341/arms-report.json
A4: Initial behavior-clone checkpoint immediately after behavior-cloning training. Both mirrored model-seat runs are pooled.
A6: Win rate with 95% Wilson CI
A7: Model deck \ Heuristic deck | B7: Blue Tempo | C7: Green Stompy | D7: Red Aggro | E7: White Weenie
A8: Blue Tempo | B8: 48.8% [44.6%, 53.1%] | C8: 13.8% [11.2%, 16.8%] | D8: 23.6% [19.9%, 27.8%] | E8: 17.0% [13.8%, 20.8%]
A9: Green Stompy | B9: 80.7% [77.3%, 83.7%] | C9: 34.4% [29.6%, 39.6%] | D9: 57.7% [53.5%, 61.9%] | E9: 35.4% [31.5%, 39.4%]
A10: Red Aggro | B10: 53.6% [49.0%, 58.2%] | C10: 18.1% [15.1%, 21.6%] | D10: 16.7% [13.2%, 20.9%] | E10: 14.9% [12.3%, 18.0%]
A11: White Weenie | B11: 81.4% [77.5%, 84.7%] | C11: 42.3% [38.3%, 46.5%] | D11: 65.2% [61.4%, 68.9%] | E11: 37.0% [32.7%, 41.5%]
A14: Model/row wins
A15: Model deck \ Heuristic deck | B15: Blue Tempo | C15: Green Stompy | D15: Red Aggro | E15: White Weenie
A16: Blue Tempo | B16: 254 | C16: 80 | D16: 104 | E16: 75
A17: Green Stompy | B17: 468 | C17: 117 | D17: 306 | E17: 198
A18: Red Aggro | B18: 236 | C18: 96 | D18: 60 | E18: 91
A19: White Weenie | B19: 358 | C19: 237 | D19: 398 | E19: 170
A21: Total games in denominator
A22: Model deck \ Heuristic deck | B22: Blue Tempo | C22: Green Stompy | D22: Red Aggro | E22: White Weenie
A23: Blue Tempo | B23: 520 | C23: 580 | D23: 440 | E23: 440
A24: Green Stompy | B24: 580 | C24: 340 | D24: 530 | E24: 560
A25: Red Aggro | B25: 440 | C25: 530 | D25: 360 | E25: 610
A26: White Weenie | B26: 440 | C26: 560 | D26: 610 | E26: 460
A28: Decisive games
A29: Model deck \ Heuristic deck | B29: Blue Tempo | C29: Green Stompy | D29: Red Aggro | E29: White Weenie
A30: Blue Tempo | B30: 516 | C30: 580 | D30: 440 | E30: 440
A31: Green Stompy | B31: 580 | C31: 338 | D31: 530 | E31: 560
A32: Red Aggro | B32: 440 | C32: 527 | D32: 360 | E32: 610
A33: White Weenie | B33: 440 | C33: 560 | D33: 610 | E33: 460
A35: Non-decisive/crash games
A36: Model deck \ Heuristic deck | B36: Blue Tempo | C36: Green Stompy | D36: Red Aggro | E36: White Weenie
A37: Blue Tempo | B37: 4 | C37: 0 | D37: 0 | E37: 0
A38: Green Stompy | B38: 0 | C38: 2 | D38: 0 | E38: 0
A39: Red Aggro | B39: 0 | C39: 3 | D39: 0 | E39: 0
A40: White Weenie | B40: 0 | C40: 0 | D40: 0 | E40: 0
A42: Draw-clock markers
A43: Model deck \ Heuristic deck | B43: Blue Tempo | C43: Green Stompy | D43: Red Aggro | E43: White Weenie
A44: Blue Tempo | B44: 0 | C44: 0 | D44: 0 | E44: 0
A45: Green Stompy | B45: 0 | C45: 2 | D45: 0 | E45: 0
A46: Red Aggro | B46: 0 | C46: 0 | D46: 0 | E46: 0
A47: White Weenie | B47: 0 | C47: 1 | D47: 0 | E47: 1
...

Sheet RL_iter05
A1: RL checkpoint after iteration 5 — 4,000 eval games
A2: Rows: Model deck; columns: Heuristic deck.
A3: Source: data/training/constructed-four-rl-4000/iter-004/arms-report.json
A4: Both mirrored model-seat runs are pooled; crashes/non-won games count as non-model wins, matching arms-report.json.
A6: Win rate with 95% Wilson CI
A7: Model deck \ Heuristic deck | B7: Blue Tempo | C7: Green Stompy | D7: Red Aggro | E7: White Weenie
A8: Blue Tempo | B8: 52.8% [46.6%, 58.9%] | C8: 17.6% [13.4%, 22.8%] | D8: 26.8% [21.7%, 32.6%] | E8: 18.8% [14.4%, 24.1%]
A9: Green Stompy | B9: 84.0% [78.9%, 88.0%] | C9: 41.6% [35.7%, 47.8%] | D9: 66.4% [60.3%, 72.0%] | E9: 39.2% [33.4%, 45.4%]
A10: Red Aggro | B10: 65.2% [59.1%, 70.8%] | C10: 16.0% [12.0%, 21.1%] | D10: 25.2% [20.2%, 30.9%] | E10: 17.6% [13.4%, 22.8%]
A11: White Weenie | B11: 86.4% [81.6%, 90.1%] | C11: 33.6% [28.0%, 39.7%] | D11: 69.2% [63.2%, 74.6%] | E11: 39.2% [33.4%, 45.4%]
A14: Model/row wins
A15: Model deck \ Heuristic deck | B15: Blue Tempo | C15: Green Stompy | D15: Red Aggro | E15: White Weenie
A16: Blue Tempo | B16: 132 | C16: 44 | D16: 67 | E16: 47
A17: Green Stompy | B17: 210 | C17: 104 | D17: 166 | E17: 98
A18: Red Aggro | B18: 163 | C18: 40 | D18: 63 | E18: 44
A19: White Weenie | B19: 216 | C19: 84 | D19: 173 | E19: 98
A21: Total games in denominator
A22: Model deck \ Heuristic deck | B22: Blue Tempo | C22: Green Stompy | D22: Red Aggro | E22: White Weenie
A23: Blue Tempo | B23: 250 | C23: 250 | D23: 250 | E23: 250
A24: Green Stompy | B24: 250 | C24: 250 | D24: 250 | E24: 250
A25: Red Aggro | B25: 250 | C25: 250 | D25: 250 | E25: 250
A26: White Weenie | B26: 250 | C26: 250 | D26: 250 | E26: 250
A28: Decisive games
A29: Model deck \ Heuristic deck | B29: Blue Tempo | C29: Green Stompy | D29: Red Aggro | E29: White Weenie
A30: Blue Tempo | B30: 250 | C30: 250 | D30: 249 | E30: 250
A31: Green Stompy | B31: 250 | C31: 250 | D31: 250 | E31: 250
A32: Red Aggro | B32: 248 | C32: 250 | D32: 250 | E32: 250
A33: White Weenie | B33: 250 | C33: 250 | D33: 247 | E33: 250
A35: Non-decisive/crash games
A36: Model deck \ Heuristic deck | B36: Blue Tempo | C36: Green Stompy | D36: Red Aggro | E36: White Weenie
A37: Blue Tempo | B37: 0 | C37: 0 | D37: 1 | E37: 0
A38: Green Stompy | B38: 0 | C38: 0 | D38: 0 | E38: 0
A39: Red Aggro | B39: 2 | C39: 0 | D39: 0 | E39: 0
A40: White Weenie | B40: 0 | C40: 0 | D40: 3 | E40: 0
A42: Draw-clock markers
A43: Model deck \ Heuristic deck | B43: Blue Tempo | C43: Green Stompy | D43: Red Aggro | E43: White Weenie
A44: Blue Tempo | B44: 0 | C44: 0 | D44: 0 | E44: 0
A45: Green Stompy | B45: 0 | C45: 0 | D45: 0 | E45: 0
A46: Red Aggro | B46: 0 | C46: 0 | D46: 0 | E46: 0
A47: White Weenie | B47: 0 | C47: 0 | D47: 0 | E47: 0
...

Sheet RL_iter10
A1: RL checkpoint after iteration 10 — 4,000 eval games
A2: Rows: Model deck; columns: Heuristic deck.
A3: Source: data/training/constructed-four-rl-4000/iter-009/arms-report.json
A4: Both mirrored model-seat runs are pooled; crashes/non-won games count as non-model wins, matching arms-report.json.
A6: Win rate with 95% Wilson CI
A7: Model deck \ Heuristic deck | B7: Blue Tempo | C7: Green Stompy | D7: Red Aggro | E7: White Weenie
A8: Blue Tempo | B8: 56.8% [50.6%, 62.8%] | C8: 14.0% [10.2%, 18.8%] | D8: 25.6% [20.6%, 31.4%] | E8: 20.4% [15.9%, 25.8%]
A9: Green Stompy | B9: 86.8% [82.0%, 90.4%] | C9: 42.8% [36.8%, 49.0%] | D9: 63.6% [57.5%, 69.3%] | E9: 50.8% [44.6%, 56.9%]
A10: Red Aggro | B10: 66.8% [60.7%, 72.3%] | C10: 20.4% [15.9%, 25.8%] | D10: 28.0% [22.8%, 33.9%] | E10: 17.6% [13.4%, 22.8%]
A11: White Weenie | B11: 86.0% [81.2%, 89.8%] | C11: 30.0% [24.7%, 35.9%] | D11: 70.0% [64.1%, 75.3%] | E11: 42.4% [36.4%, 48.6%]
A14: Model/row wins
A15: Model deck \ Heuristic deck | B15: Blue Tempo | C15: Green Stompy | D15: Red Aggro | E15: White Weenie
A16: Blue Tempo | B16: 142 | C16: 35 | D16: 64 | E16: 51
A17: Green Stompy | B17: 217 | C17: 107 | D17: 159 | E17: 127
A18: Red Aggro | B18: 167 | C18: 51 | D18: 70 | E18: 44
A19: White Weenie | B19: 215 | C19: 75 | D19: 175 | E19: 106
A21: Total games in denominator
A22: Model deck \ Heuristic deck | B22: Blue Tempo | C22: Green Stompy | D22: Red Aggro | E22: White Weenie
A23: Blue Tempo | B23: 250 | C23: 250 | D23: 250 | E23: 250
A24: Green Stompy | B24: 250 | C24: 250 | D24: 250 | E24: 250
A25: Red Aggro | B25: 250 | C25: 250 | D25: 250 | E25: 250
A26: White Weenie | B26: 250 | C26: 250 | D26: 250 | E26: 250
A28: Decisive games
A29: Model deck \ Heuristic deck | B29: Blue Tempo | C29: Green Stompy | D29: Red Aggro | E29: White Weenie
A30: Blue Tempo | B30: 250 | C30: 250 | D30: 249 | E30: 250
A31: Green Stompy | B31: 250 | C31: 250 | D31: 250 | E31: 250
A32: Red Aggro | B32: 248 | C32: 250 | D32: 250 | E32: 250
A33: White Weenie | B33: 250 | C33: 250 | D33: 247 | E33: 250
A35: Non-decisive/crash games
A36: Model deck \ Heuristic deck | B36: Blue Tempo | C36: Green Stompy | D36: Red Aggro | E36: White Weenie
A37: Blue Tempo | B37: 0 | C37: 0 | D37: 1 | E37: 0
A38: Green Stompy | B38: 0 | C38: 0 | D38: 0 | E38: 0
A39: Red Aggro | B39: 2 | C39: 0 | D39: 0 | E39: 0
A40: White Weenie | B40: 0 | C40: 0 | D40: 3 | E40: 0
A42: Draw-clock markers
A43: Model deck \ Heuristic deck | B43: Blue Tempo | C43: Green Stompy | D43: Red Aggro | E43: White Weenie
A44: Blue Tempo | B44: 0 | C44: 0 | D44: 0 | E44: 0
A45: Green Stompy | B45: 0 | C45: 0 | D45: 0 | E45: 0
A46: Red Aggro | B46: 0 | C46: 0 | D46: 0 | E46: 0
A47: White Weenie | B47: 0 | C47: 0 | D47: 0 | E47: 0
...

Sheet RL_iter15
A1: RL checkpoint after iteration 15 — 4,000 eval games
A2: Rows: Model deck; columns: Heuristic deck.
A3: Source: data/training/constructed-four-rl-4000/iter-014/arms-report.json
A4: Both mirrored model-seat runs are pooled; crashes/non-won games count as non-model wins, matching arms-report.json.
A6: Win rate with 95% Wilson CI
A7: Model deck \ Heuristic deck | B7: Blue Tempo | C7: Green Stompy | D7: Red Aggro | E7: White Weenie
A8: Blue Tempo | B8: 54.4% [48.2%, 60.5%] | C8: 21.2% [16.6%, 26.7%] | D8: 27.2% [22.1%, 33.0%] | E8: 25.2% [20.2%, 30.9%]
A9: Green Stompy | B9: 82.8% [77.6%, 87.0%] | C9: 49.2% [43.1%, 55.4%] | D9: 65.6% [59.5%, 71.2%] | E9: 42.0% [36.0%, 48.2%]
A10: Red Aggro | B10: 75.6% [69.9%, 80.5%] | C10: 31.2% [25.8%, 37.2%] | D10: 29.6% [24.3%, 35.5%] | E10: 26.0% [21.0%, 31.8%]
A11: White Weenie | B11: 84.8% [79.8%, 88.7%] | C11: 49.6% [43.5%, 55.8%] | D11: 74.4% [68.6%, 79.4%] | E11: 48.4% [42.3%, 54.6%]
A14: Model/row wins
A15: Model deck \ Heuristic deck | B15: Blue Tempo | C15: Green Stompy | D15: Red Aggro | E15: White Weenie
A16: Blue Tempo | B16: 136 | C16: 53 | D16: 68 | E16: 63
A17: Green Stompy | B17: 207 | C17: 123 | D17: 164 | E17: 105
A18: Red Aggro | B18: 189 | C18: 78 | D18: 74 | E18: 65
A19: White Weenie | B19: 212 | C19: 124 | D19: 186 | E19: 121
A21: Total games in denominator
A22: Model deck \ Heuristic deck | B22: Blue Tempo | C22: Green Stompy | D22: Red Aggro | E22: White Weenie
A23: Blue Tempo | B23: 250 | C23: 250 | D23: 250 | E23: 250
A24: Green Stompy | B24: 250 | C24: 250 | D24: 250 | E24: 250
A25: Red Aggro | B25: 250 | C25: 250 | D25: 250 | E25: 250
A26: White Weenie | B26: 250 | C26: 250 | D26: 250 | E26: 250
A28: Decisive games
A29: Model deck \ Heuristic deck | B29: Blue Tempo | C29: Green Stompy | D29: Red Aggro | E29: White Weenie
A30: Blue Tempo | B30: 250 | C30: 250 | D30: 249 | E30: 250
A31: Green Stompy | B31: 250 | C31: 250 | D31: 250 | E31: 250
A32: Red Aggro | B32: 248 | C32: 250 | D32: 250 | E32: 250
A33: White Weenie | B33: 250 | C33: 250 | D33: 247 | E33: 250
A35: Non-decisive/crash games
A36: Model deck \ Heuristic deck | B36: Blue Tempo | C36: Green Stompy | D36: Red Aggro | E36: White Weenie
A37: Blue Tempo | B37: 0 | C37: 0 | D37: 1 | E37: 0
A38: Green Stompy | B38: 0 | C38: 0 | D38: 0 | E38: 0
A39: Red Aggro | B39: 2 | C39: 0 | D39: 0 | E39: 0
A40: White Weenie | B40: 0 | C40: 0 | D40: 3 | E40: 0
A42: Draw-clock markers
A43: Model deck \ Heuristic deck | B43: Blue Tempo | C43: Green Stompy | D43: Red Aggro | E43: White Weenie
A44: Blue Tempo | B44: 0 | C44: 0 | D44: 0 | E44: 0
A45: Green Stompy | B45: 0 | C45: 0 | D45: 0 | E45: 0
A46: Red Aggro | B46: 0 | C46: 0 | D46: 0 | E46: 0
A47: White Weenie | B47: 0 | C47: 0 | D47: 0 | E47: 0
...

Sheet RL_iter20
A1: RL checkpoint after iteration 20 — 4,000 eval games
A2: Rows: Model deck; columns: Heuristic deck.
A3: Source: data/training/constructed-four-rl-4000/iter-019/arms-report.json
A4: Both mirrored model-seat runs are pooled; crashes/non-won games count as non-model wins, matching arms-report.json.
A6: Win rate with 95% Wilson CI
A7: Model deck \ Heuristic deck | B7: Blue Tempo | C7: Green Stompy | D7: Red Aggro | E7: White Weenie
A8: Blue Tempo | B8: 53.6% [47.4%, 59.7%] | C8: 22.8% [18.0%, 28.4%] | D8: 28.8% [23.5%, 34.7%] | E8: 24.0% [19.1%, 29.7%]
A9: Green Stompy | B9: 87.2% [82.5%, 90.8%] | C9: 54.8% [48.6%, 60.9%] | D9: 68.0% [62.0%, 73.5%] | E9: 50.4% [44.2%, 56.5%]
A10: Red Aggro | B10: 74.4% [68.6%, 79.4%] | C10: 30.0% [24.7%, 35.9%] | D10: 34.4% [28.8%, 40.5%] | E10: 28.0% [22.8%, 33.9%]
A11: White Weenie | B11: 83.2% [78.1%, 87.3%] | C11: 47.6% [41.5%, 53.8%] | D11: 72.8% [67.0%, 77.9%] | E11: 50.0% [43.8%, 56.2%]
A14: Model/row wins
A15: Model deck \ Heuristic deck | B15: Blue Tempo | C15: Green Stompy | D15: Red Aggro | E15: White Weenie
A16: Blue Tempo | B16: 134 | C16: 57 | D16: 72 | E16: 60
A17: Green Stompy | B17: 218 | C17: 137 | D17: 170 | E17: 126
A18: Red Aggro | B18: 186 | C18: 75 | D18: 86 | E18: 70
A19: White Weenie | B19: 208 | C19: 119 | D19: 182 | E19: 125
A21: Total games in denominator
A22: Model deck \ Heuristic deck | B22: Blue Tempo | C22: Green Stompy | D22: Red Aggro | E22: White Weenie
A23: Blue Tempo | B23: 250 | C23: 250 | D23: 250 | E23: 250
A24: Green Stompy | B24: 250 | C24: 250 | D24: 250 | E24: 250
A25: Red Aggro | B25: 250 | C25: 250 | D25: 250 | E25: 250
A26: White Weenie | B26: 250 | C26: 250 | D26: 250 | E26: 250
A28: Decisive games
A29: Model deck \ Heuristic deck | B29: Blue Tempo | C29: Green Stompy | D29: Red Aggro | E29: White Weenie
A30: Blue Tempo | B30: 250 | C30: 250 | D30: 249 | E30: 250
A31: Green Stompy | B31: 250 | C31: 250 | D31: 250 | E31: 250
A32: Red Aggro | B32: 248 | C32: 250 | D32: 250 | E32: 250
A33: White Weenie | B33: 250 | C33: 250 | D33: 247 | E33: 250
A35: Non-decisive/crash games
A36: Model deck \ Heuristic deck | B36: Blue Tempo | C36: Green Stompy | D36: Red Aggro | E36: White Weenie
A37: Blue Tempo | B37: 0 | C37: 0 | D37: 1 | E37: 0
A38: Green Stompy | B38: 0 | C38: 0 | D38: 0 | E38: 0
A39: Red Aggro | B39: 2 | C39: 0 | D39: 0 | E39: 0
A40: White Weenie | B40: 0 | C40: 0 | D40: 3 | E40: 0
A42: Draw-clock markers
A43: Model deck \ Heuristic deck | B43: Blue Tempo | C43: Green Stompy | D43: Red Aggro | E43: White Weenie
A44: Blue Tempo | B44: 0 | C44: 0 | D44: 0 | E44: 0
A45: Green Stompy | B45: 0 | C45: 0 | D45: 0 | E45: 0
A46: Red Aggro | B46: 0 | C46: 0 | D46: 0 | E46: 0
A47: White Weenie | B47: 0 | C47: 0 | D47: 0 | E47: 0
...

Sheet RL_iter30
A1: RL checkpoint after iteration 30 — 8,000 eval games
A2: Rows: Model deck; columns: Heuristic deck.
A3: Source: data/training/constructed-four-rl-4000/iter-029/arms-report.json
A4: Both mirrored model-seat runs are pooled; crashes/non-won games count as non-model wins, matching arms_report.json.
A6: Win rate with 95% Wilson CI
A7: Model deck \ Heuristic deck | B7: Blue Tempo | C7: Green Stompy | D7: Red Aggro | E7: White Weenie
A8: Blue Tempo | B8: 55.8% [51.4%, 60.1%] | C8: 25.8% [22.2%, 29.8%] | D8: 28.6% [24.8%, 32.7%] | E8: 21.4% [18.0%, 25.2%]
A9: Green Stompy | B9: 84.8% [81.4%, 87.7%] | C9: 49.4% [45.0%, 53.8%] | D9: 70.6% [66.5%, 74.4%] | E9: 47.8% [43.5%, 52.2%]
A10: Red Aggro | B10: 76.4% [72.5%, 79.9%] | C10: 26.2% [22.5%, 30.2%] | D10: 35.2% [31.1%, 39.5%] | E10: 34.4% [30.4%, 38.7%]
A11: White Weenie | B11: 90.4% [87.5%, 92.7%] | C11: 48.6% [44.2%, 53.0%] | D11: 72.2% [68.1%, 75.9%] | E11: 50.6% [46.2%, 55.0%]
A14: Model/row wins
A15: Model deck \ Heuristic deck | B15: Blue Tempo | C15: Green Stompy | D15: Red Aggro | E15: White Weenie
A16: Blue Tempo | B16: 279 | C16: 129 | D16: 143 | E16: 107
A17: Green Stompy | B17: 424 | C17: 247 | D17: 353 | E17: 239
A18: Red Aggro | B18: 382 | C18: 131 | D18: 176 | E18: 172
A19: White Weenie | B19: 452 | C19: 243 | D19: 361 | E19: 253
A21: Total games in denominator
A22: Model deck \ Heuristic deck | B22: Blue Tempo | C22: Green Stompy | D22: Red Aggro | E22: White Weenie
A23: Blue Tempo | B23: 500 | C23: 500 | D23: 500 | E23: 500
A24: Green Stompy | B24: 500 | C24: 500 | D24: 500 | E24: 500
A25: Red Aggro | B25: 500 | C25: 500 | D25: 500 | E25: 500
A26: White Weenie | B26: 500 | C26: 500 | D26: 500 | E26: 500
A28: Decisive games
A29: Model deck \ Heuristic deck | B29: Blue Tempo | C29: Green Stompy | D29: Red Aggro | E29: White Weenie
A30: Blue Tempo | B30: 500 | C30: 500 | D30: 500 | E30: 500
A31: Green Stompy | B31: 500 | C31: 500 | D31: 500 | E31: 500
A32: Red Aggro | B32: 498 | C32: 498 | D32: 500 | E32: 498
A33: White Weenie | B33: 500 | C33: 499 | D33: 500 | E33: 500
A35: Non-decisive/crash games
A36: Model deck \ Heuristic deck | B36: Blue Tempo | C36: Green Stompy | D36: Red Aggro | E36: White Weenie
A37: Blue Tempo | B37: 0 | C37: 0 | D37: 0 | E37: 0
A38: Green Stompy | B38: 0 | C38: 0 | D38: 0 | E38: 0
A39: Red Aggro | B39: 2 | C39: 2 | D39: 0 | E39: 2
A40: White Weenie | B40: 0 | C40: 1 | D40: 0 | E40: 0
A42: Draw-clock markers
A43: Model deck \ Heuristic deck | B43: Blue Tempo | C43: Green Stompy | D43: Red Aggro | E43: White Weenie
A44: Blue Tempo | B44: 0 | C44: 0 | D44: 0 | E44: 0
A45: Green Stompy | B45: 0 | C45: 0 | D45: 0 | E45: 0
A46: Red Aggro | B46: 0 | C46: 0 | D46: 0 | E46: 0
A47: White Weenie | B47: 0 | C47: 0 | D47: 0 | E47: 0
...

Sheet RL_iter40
A1: RL checkpoint after iteration 40 — 8,000 eval games
A2: Rows: Model deck; columns: Heuristic deck.
A3: Source: data/training/constructed-four-rl-4000/iter-039/arms-report.json
A4: Both mirrored model-seat runs are pooled; crashes/non-won games count as non-model wins, matching arms_report.json.
A6: Win rate with 95% Wilson CI
A7: Model deck \ Heuristic deck | B7: Blue Tempo | C7: Green Stompy | D7: Red Aggro | E7: White Weenie
A8: Blue Tempo | B8: 52.6% [48.2%, 56.9%] | C8: 20.2% [16.9%, 23.9%] | D8: 24.8% [21.2%, 28.8%] | E8: 22.4% [19.0%, 26.3%]
A9: Green Stompy | B9: 84.0% [80.5%, 87.0%] | C9: 48.6% [44.2%, 53.0%] | D9: 69.8% [65.6%, 73.7%] | E9: 45.6% [41.3%, 50.0%]
A10: Red Aggro | B10: 80.8% [77.1%, 84.0%] | C10: 26.4% [22.7%, 30.4%] | D10: 38.8% [34.6%, 43.1%] | E10: 40.2% [36.0%, 44.6%]
A11: White Weenie | B11: 88.8% [85.7%, 91.3%] | C11: 43.2% [38.9%, 47.6%] | D11: 73.8% [69.8%, 77.5%] | E11: 50.2% [45.8%, 54.6%]
A14: Model/row wins
A15: Model deck \ Heuristic deck | B15: Blue Tempo | C15: Green Stompy | D15: Red Aggro | E15: White Weenie
A16: Blue Tempo | B16: 263 | C16: 101 | D16: 124 | E16: 112
A17: Green Stompy | B17: 420 | C17: 243 | D17: 349 | E17: 228
A18: Red Aggro | B18: 404 | C18: 132 | D18: 194 | E18: 201
A19: White Weenie | B19: 444 | C19: 216 | D19: 369 | E19: 251
A21: Total games in denominator
A22: Model deck \ Heuristic deck | B22: Blue Tempo | C22: Green Stompy | D22: Red Aggro | E22: White Weenie
A23: Blue Tempo | B23: 500 | C23: 500 | D23: 500 | E23: 500
A24: Green Stompy | B24: 500 | C24: 500 | D24: 500 | E24: 500
A25: Red Aggro | B25: 500 | C25: 500 | D25: 500 | E25: 500
A26: White Weenie | B26: 500 | C26: 500 | D26: 500 | E26: 500
A28: Decisive games
A29: Model deck \ Heuristic deck | B29: Blue Tempo | C29: Green Stompy | D29: Red Aggro | E29: White Weenie
A30: Blue Tempo | B30: 500 | C30: 500 | D30: 500 | E30: 500
A31: Green Stompy | B31: 500 | C31: 500 | D31: 500 | E31: 500
A32: Red Aggro | B32: 498 | C32: 497 | D32: 500 | E32: 498
A33: White Weenie | B33: 500 | C33: 498 | D33: 500 | E33: 500
A35: Non-decisive/crash games
A36: Model deck \ Heuristic deck | B36: Blue Tempo | C36: Green Stompy | D36: Red Aggro | E36: White Weenie
A37: Blue Tempo | B37: 0 | C37: 0 | D37: 0 | E37: 0
A38: Green Stompy | B38: 0 | C38: 0 | D38: 0 | E38: 0
A39: Red Aggro | B39: 2 | C39: 3 | D39: 0 | E39: 2
A40: White Weenie | B40: 0 | C40: 2 | D40: 0 | E40: 0
A42: Draw-clock markers
A43: Model deck \ Heuristic deck | B43: Blue Tempo | C43: Green Stompy | D43: Red Aggro | E43: White Weenie
A44: Blue Tempo | B44: 0 | C44: 0 | D44: 0 | E44: 0
A45: Green Stompy | B45: 0 | C45: 0 | D45: 0 | E45: 0
A46: Red Aggro | B46: 0 | C46: 0 | D46: 0 | E46: 0
A47: White Weenie | B47: 0 | C47: 0 | D47: 0 | E47: 0
...

Sheet RL30_vs_Baselines
A1: RL iteration 30 comparison
A2: Cells are percentage-point changes in model win rate (row deck versus column deck).
A3: Positive values mean the iteration-30 model won more often than the reference.
A4: For HvH, diagonal references use the 50% mirror-match expectation; off-diagonals use the observed HvH matrix.
A5: References: HvH_40000 and BC_initial_8000 sheets.
A6: RL_iter30 - HvH_40000 | G6: RL_iter30 - BC_initial_8000
A7: Model deck / reference deck | B7: Blue Tempo | C7: Green Stompy | D7: Red Aggro | E7: White Weenie | G7: Model deck / reference deck | H7: Blue Tempo | I7: Green Stompy | J7: Red Aggro | K7: White Weenie
A8: Blue Tempo | B8: 0.058 | C8: 0.10687526 | D8: 0.021456476 | E8: 0.050530612 | G8: Blue Tempo | H8: 0.069538462 | I8: 0.12006897 | J8: 0.049636364 | K8: 0.043545455
A9: Green Stompy | B9: -0.00087525562 | C9: -0.006 | D9: 0.043966805 | E9: -0.032019646 | G9: Green Stompy | H9: 0.041103448 | I9: 0.14988235 | J9: 0.12864151 | K9: 0.12442857
A10: Red Aggro | B10: 0.028543524 | C10: -0.075966805 | D10: -0.148 | E10: 0.022165138 | G10: Red Aggro | H10: 0.22763636 | I10: 0.080867925 | J10: 0.18533333 | K10: 0.19481967
A11: White Weenie | B11: 0.067469388 | C11: -0.0039803536 | D11: 0.043834862 | E11: 0.006 | G11: White Weenie | H11: 0.090363636 | I11: 0.062785714 | J11: 0.069540984 | K11: 0.13643478
A13: Overall model win-rate change
A14: vs HvH (50%): | B14: 0.011375 | C14: vs initial BC: | D14: 0.105375
A15: Overall model win rate: 51.14%

Sheet RL40_vs_Baselines
A1: RL iteration 40 comparison
A2: Cells are percentage-point changes in model win rate (row deck versus column deck).
A3: Positive values mean the iteration-40 model won more often than the reference.
A4: For HvH, diagonal references use the 50% mirror-match expectation; off-diagonals use the observed HvH matrix.
A5: References: HvH_40000 and BC_initial_8000 sheets.
A6: RL_iter40 - HvH_40000 | G6: RL_iter40 - BC_initial_8000
A7: Model deck / reference deck | B7: Blue Tempo | C7: Green Stompy | D7: Red Aggro | E7: White Weenie | G7: Model deck / reference deck | H7: Blue Tempo | I7: Green Stompy | J7: Red Aggro | K7: White Weenie
A8: Blue Tempo | B8: 0.026 | C8: 0.050875256 | D8: -0.016543524 | E8: 0.060530612 | G8: Blue Tempo | H8: 0.037538462 | I8: 0.064068966 | J8: 0.011636364 | K8: 0.053545455
A9: Green Stompy | B9: -0.0088752556 | C9: -0.014 | D9: 0.035966805 | E9: -0.054019646 | G9: Green Stompy | H9: 0.033103448 | I9: 0.14188235 | J9: 0.12064151 | K9: 0.10242857
A10: Red Aggro | B10: 0.072543524 | C10: -0.073966805 | D10: -0.112 | E10: 0.080165138 | G10: Red Aggro | H10: 0.27163636 | I10: 0.082867925 | J10: 0.22133333 | K10: 0.25281967
A11: White Weenie | B11: 0.051469388 | C11: -0.057980354 | D11: 0.059834862 | E11: 0.002 | G11: White Weenie | H11: 0.074363636 | I11: 0.0087857143 | J11: 0.085540984 | K11: 0.13243478
A13: Overall model win-rate change
A14: vs HvH (50%): | B14: 0.006375 | C14: vs initial BC: | D14: 0.100375
A15: Overall model win rate: 50.64%

Sheet RL40_vs_RL30
A1: RL iteration 40 versus iteration 30
A2: Cells are percentage-point changes in model win rate (RL_iter40 minus RL_iter30).
A3: Positive values mean the iteration-40 model performed better for that row/column matchup.
A4: This is the direct per-matchup comparison for checking whether training gains have plateaued.
A5: References: RL_iter40 and RL_iter30 sheets.
A6: RL_iter40 - RL_iter30
A7: Model deck / reference deck | B7: Blue Tempo | C7: Green Stompy | D7: Red Aggro | E7: White Weenie
A8: Blue Tempo | B8: -0.032 | C8: -0.056 | D8: -0.038 | E8: 0.01
A9: Green Stompy | B9: -0.008 | C9: -0.008 | D9: -0.008 | E9: -0.022
A10: Red Aggro | B10: 0.044 | C10: 0.002 | D10: 0.036 | E10: 0.058
A11: White Weenie | B11: -0.016 | C11: -0.054 | D11: 0.016 | E11: -0.004
A13: Overall model win-rate change
A14: RL_iter40 - RL_iter30: | B14: -0.005
A15: Overall: 50.64% versus 51.14%

Sheet All_Matrices_Combined
A1: All matchup matrices and comparisons
A2: Actual matrices include observed win rate and 95% confidence interval.
A3: Comparison matrices show percentage-point changes; positive values favor the first-named model.
A4: Rows are the first/row deck and columns are the second/column deck. HvH diagonal comparisons use the 50% mirror expectation.
A5: Actual win-rate matrices (with 95% CIs)
A6: HvH_40000 | G6: BC_initial_8000
A7: Model deck / reference deck | B7: Blue Tempo | C7: Green Stompy | D7: Red Aggro | E7: White Weenie | G7: Model deck / reference deck | H7: Blue Tempo | I7: Green Stompy | J7: Red Aggro | K7: White Weenie | M7: Sheet | N7: Evaluation | O7: Games | P7: Model/row wins | Q7: Decisive | R7: Non-decisive | S7: Overall model win rate | T7: 95% CI
A8: Blue Tempo | B8: =HvH_40000!B8 -> 51.3% [49.3%, 53.2%] | C8: =HvH_40000!C8 -> 15.1% [14.1%, 16.1%] | D8: =HvH_40000!D8 -> 26.5% [25.2%, 27.7%] | E8: =HvH_40000!E8 -> 16.3% [15.3%, 17.4%] | G8: Blue Tempo | H8: =BC_initial_8000!B8 -> 48.8% [44.6%, 53.1%] | I8: =BC_initial_8000!C8 -> 13.8% [11.2%, 16.8%] | J8: =BC_initial_8000!D8 -> 23.6% [19.9%, 27.8%] | K8: =BC_initial_8000!E8 -> 17.0% [13.8%, 20.8%] | M8: HvH_40000 | N8: Heuristic vs heuristic — 40,000 generated games | O8: 40000 | Q8: 40000 | R8: 0
A9: Green Stompy | B9: =HvH_40000!B9 -> 84.9% [83.9%, 85.9%] | C9: =HvH_40000!C9 -> 50.9% [48.9%, 52.8%] | D9: =HvH_40000!D9 -> 66.2% [64.9%, 67.5%] | E9: =HvH_40000!E9 -> 51.0% [49.6%, 52.4%] | G9: Green Stompy | H9: =BC_initial_8000!B9 -> 80.7% [77.3%, 83.7%] | I9: =BC_initial_8000!C9 -> 34.4% [29.6%, 39.6%] | J9: =BC_initial_8000!D9 -> 57.7% [53.5%, 61.9%] | K9: =BC_initial_8000!E9 -> 35.4% [31.5%, 39.4%] | M9: BC_initial_8000 | N9: Initial behavior clone vs heuristic — 8,000 games | O9: 8000 | P9: 3248 | Q9: 7991 | R9: 9 | S9: 0.406 | T9: [39.5%, 41.7%]
A10: Red Aggro | B10: =HvH_40000!B10 -> 73.5% [72.3%, 74.8%] | C10: =HvH_40000!C10 -> 33.8% [32.5%, 35.1%] | D10: =HvH_40000!D10 -> 51.6% [49.6%, 53.6%] | E10: =HvH_40000!E10 -> 32.2% [31.0%, 33.4%] | G10: Red Aggro | H10: =BC_initial_8000!B10 -> 53.6% [49.0%, 58.2%] | I10: =BC_initial_8000!C10 -> 18.1% [15.1%, 21.6%] | J10: =BC_initial_8000!D10 -> 16.7% [13.2%, 20.9%] | K10: =BC_initial_8000!E10 -> 14.9% [12.3%, 18.0%] | M10: RL_iter30 | N10: RL checkpoint after iteration 30 — 8,000 eval games | O10: 8000 | P10: 4091 | Q10: 7993 | R10: 7 | S10: 0.511375 | T10: [50.0%, 52.2%]
A11: White Weenie | B11: =HvH_40000!B11 -> 83.7% [82.6%, 84.7%] | C11: =HvH_40000!C11 -> 49.0% [47.6%, 50.4%] | D11: =HvH_40000!D11 -> 67.8% [66.6%, 69.0%] | E11: =HvH_40000!E11 -> 52.8% [50.9%, 54.7%] | G11: White Weenie | H11: =BC_initial_8000!B11 -> 81.4% [77.5%, 84.7%] | I11: =BC_initial_8000!C11 -> 42.3% [38.3%, 46.5%] | J11: =BC_initial_8000!D11 -> 65.2% [61.4%, 68.9%] | K11: =BC_initial_8000!E11 -> 37.0% [32.7%, 41.5%] | M11: RL_iter40 | N11: RL checkpoint after iteration 40 — 8,000 eval games | O11: 8000 | P11: 4051 | Q11: 7991 | R11: 9 | S11: 0.506375 | T11: [49.5%, 51.7%]
A13: RL_iter30 | G13: RL_iter40
A14: Model deck / reference deck | B14: Blue Tempo | C14: Green Stompy | D14: Red Aggro | E14: White Weenie | G14: Model deck / reference deck | H14: Blue Tempo | I14: Green Stompy | J14: Red Aggro | K14: White Weenie
A15: Blue Tempo | B15: =RL_iter30!B8 -> 55.8% [51.4%, 60.1%] | C15: =RL_iter30!C8 -> 25.8% [22.2%, 29.8%] | D15: =RL_iter30!D8 -> 28.6% [24.8%, 32.7%] | E15: =RL_iter30!E8 -> 21.4% [18.0%, 25.2%] | G15: Blue Tempo | H15: =RL_iter40!B8 -> 52.6% [48.2%, 56.9%] | I15: =RL_iter40!C8 -> 20.2% [16.9%, 23.9%] | J15: =RL_iter40!D8 -> 24.8% [21.2%, 28.8%] | K15: =RL_iter40!E8 -> 22.4% [19.0%, 26.3%]
A16: Green Stompy | B16: =RL_iter30!B9 -> 84.8% [81.4%, 87.7%] | C16: =RL_iter30!C9 -> 49.4% [45.0%, 53.8%] | D16: =RL_iter30!D9 -> 70.6% [66.5%, 74.4%] | E16: =RL_iter30!E9 -> 47.8% [43.5%, 52.2%] | G16: Green Stompy | H16: =RL_iter40!B9 -> 84.0% [80.5%, 87.0%] | I16: =RL_iter40!C9 -> 48.6% [44.2%, 53.0%] | J16: =RL_iter40!D9 -> 69.8% [65.6%, 73.7%] | K16: =RL_iter40!E9 -> 45.6% [41.3%, 50.0%]
A17: Red Aggro | B17: =RL_iter30!B10 -> 76.4% [72.5%, 79.9%] | C17: =RL_iter30!C10 -> 26.2% [22.5%, 30.2%] | D17: =RL_iter30!D10 -> 35.2% [31.1%, 39.5%] | E17: =RL_iter30!E10 -> 34.4% [30.4%, 38.7%] | G17: Red Aggro | H17: =RL_iter40!B10 -> 80.8% [77.1%, 84.0%] | I17: =RL_iter40!C10 -> 26.4% [22.7%, 30.4%] | J17: =RL_iter40!D10 -> 38.8% [34.6%, 43.1%] | K17: =RL_iter40!E10 -> 40.2% [36.0%, 44.6%]
A18: White Weenie | B18: =RL_iter30!B11 -> 90.4% [87.5%, 92.7%] | C18: =RL_iter30!C11 -> 48.6% [44.2%, 53.0%] | D18: =RL_iter30!D11 -> 72.2% [68.1%, 75.9%] | E18: =RL_iter30!E11 -> 50.6% [46.2%, 55.0%] | G18: White Weenie | H18: =RL_iter40!B11 -> 88.8% [85.7%, 91.3%] | I18: =RL_iter40!C11 -> 43.2% [38.9%, 47.6%] | J18: =RL_iter40!D11 -> 73.8% [69.8%, 77.5%] | K18: =RL_iter40!E11 -> 50.2% [45.8%, 54.6%]
A20: Comparison matrices (percentage-point changes)
A21: RL_iter30 - HvH_40000 | G21: RL_iter30 - BC_initial_8000
A22: Model deck / reference deck | B22: Blue Tempo | C22: Green Stompy | D22: Red Aggro | E22: White Weenie | G22: Model deck / reference deck | H22: Blue Tempo | I22: Green Stompy | J22: Red Aggro | K22: White Weenie
A23: Blue Tempo | B23: =_xlfn.NUMBERVALUE(_xlfn.TEXTBEFORE(RL_iter30!B8, "%"))/100-50/100 -> 0.058 | C23: =_xlfn.NUMBERVALUE(_xlfn.TEXTBEFORE(RL_iter30!C8, "%"))/100-_xlfn.SINGLE(_xlfn.NUMBERVALUE(_xlfn.TEXTBEFORE(HvH_40000!C8, "%")))/100 -> 0.107 | D23: =_xlfn.SINGLE(_xlfn.NUMBERVALUE(_xlfn.TEXTBEFORE(RL_iter30!D8, "%")))/100-_xlfn.SINGLE(_xlfn.NUMBERVALUE(_xlfn.TEXTBEFORE(HvH_40000!D8, "%")))/100 -> 0.021 | E23: =_xlfn.SINGLE(_xlfn.NUMBERVALUE(_xlfn.TEXTBEFORE(RL_iter30!E8, "%")))/100-_xlfn.SINGLE(_xlfn.NUMBERVALUE(_xlfn.TEXTBEFORE(HvH_40000!E8, "%")))/100 -> 0.051 | G23: Blue Tempo | H23: =_xlfn.SINGLE(_xlfn.NUMBERVALUE(_xlfn.TEXTBEFORE(RL_iter30!B8, "%")))/100-_xlfn.SINGLE(_xlfn.NUMBERVALUE(_xlfn.TEXTBEFORE(BC_initial_8000!B8, "%")))/100 -> 0.07 | I23: =_xlfn.SINGLE(_xlfn.NUMBERVALUE(_xlfn.TEXTBEFORE(RL_iter30!C8, "%")))/100-_xlfn.SINGLE(_xlfn.NUMBERVALUE(_xlfn.TEXTBEFORE(BC_initial_8000!C8, "%")))/100 -> 0.12 | J23: =_xlfn.SINGLE(_xlfn.NUMBERVALUE(_xlfn.TEXTBEFORE(RL_iter30!D8, "%")))/100-_xlfn.SINGLE(_xlfn.NUMBERVALUE(_xlfn.TEXTBEFORE(BC_initial_8000!D8, "%")))/100 -> 0.05 | K23: =_xlfn.SINGLE(_xlfn.NUMBERVALUE(_xlfn.TEXTBEFORE(RL_iter30!E8, "%")))/100-_xlfn.SINGLE(_xlfn.NUMBERVALUE(_xlfn.TEXTBEFORE(BC_initial_8000!E8, "%")))/100 -> 0.044
A24: Green Stompy | B24: =_xlfn.NUMBERVALUE(_xlfn.TEXTBEFORE(RL_iter30!B9, "%"))/100-_xlfn.NUMBERVALUE(_xlfn.TEXTBEFORE(HvH_40000!B9, "%"))/100 -> -0.001 | C24: =_xlfn.SINGLE(_xlfn.NUMBERVALUE(_xlfn.TEXTBEFORE(RL_iter30!C9, "%")))/100-50/100 -> -0.006 | D24: =_xlfn.SINGLE(_xlfn.NUMBERVALUE(_xlfn.TEXTBEFORE(RL_iter30!D9, "%")))/100-_xlfn.SINGLE(_xlfn.NUMBERVALUE(_xlfn.TEXTBEFORE(HvH_40000!D9, "%")))/100 -> 0.044 | E24: =_xlfn.SINGLE(_xlfn.NUMBERVALUE(_xlfn.TEXTBEFORE(RL_iter30!E9, "%")))/100-_xlfn.SINGLE(_xlfn.NUMBERVALUE(_xlfn.TEXTBEFORE(HvH_40000!E9, "%")))/100 -> -0.032 | G24: Green Stompy | H24: =_xlfn.SINGLE(_xlfn.NUMBERVALUE(_xlfn.TEXTBEFORE(RL_iter30!B9, "%")))/100-_xlfn.SINGLE(_xlfn.NUMBERVALUE(_xlfn.TEXTBEFORE(BC_initial_8000!B9, "%")))/100 -> 0.041 | I24: =_xlfn.SINGLE(_xlfn.NUMBERVALUE(_xlfn.TEXTBEFORE(RL_iter30!C9, "%")))/100-_xlfn.SINGLE(_xlfn.NUMBERVALUE(_xlfn.TEXTBEFORE(BC_initial_8000!C9, "%")))/100 -> 0.15 | J24: =_xlfn.SINGLE(_xlfn.NUMBERVALUE(_xlfn.TEXTBEFORE(RL_iter30!D9, "%")))/100-_xlfn.SINGLE(_xlfn.NUMBERVALUE(_xlfn.TEXTBEFORE(BC_initial_8000!D9, "%")))/100 -> 0.129 | K24: =_xlfn.SINGLE(_xlfn.NUMBERVALUE(_xlfn.TEXTBEFORE(RL_iter30!E9, "%")))/100-_xlfn.SINGLE(_xlfn.NUMBERVALUE(_xlfn.TEXTBEFORE(BC_initial_8000!E9, "%")))/100 -> 0.124
A25: Red Aggro | B25: =_xlfn.NUMBERVALUE(_xlfn.TEXTBEFORE(RL_iter30!B10, "%"))/100-_xlfn.NUMBERVALUE(_xlfn.TEXTBEFORE(HvH_40000!B10, "%"))/100 -> 0.029 | C25: =_xlfn.SINGLE(_xlfn.NUMBERVALUE(_xlfn.TEXTBEFORE(RL_iter30!C10, "%")))/100-_xlfn.SINGLE(_xlfn.NUMBERVALUE(_xlfn.TEXTBEFORE(HvH_40000!C10, "%")))/100 -> -0.076 | D25: =_xlfn.SINGLE(_xlfn.NUMBERVALUE(_xlfn.TEXTBEFORE(RL_iter30!D10, "%")))/100-50/100 -> -0.148 | E25: =_xlfn.SINGLE(_xlfn.NUMBERVALUE(_xlfn.TEXTBEFORE(RL_iter30!E10, "%")))/100-_xlfn.SINGLE(_xlfn.NUMBERVALUE(_xlfn.TEXTBEFORE(HvH_40000!E10, "%")))/100 -> 0.022 | G25: Red Aggro | H25: =_xlfn.SINGLE(_xlfn.NUMBERVALUE(_xlfn.TEXTBEFORE(RL_iter30!B10, "%")))/100-_xlfn.SINGLE(_xlfn.NUMBERVALUE(_xlfn.TEXTBEFORE(BC_initial_8000!B10, "%")))/100 -> 0.228 | I25: =_xlfn.SINGLE(_xlfn.NUMBERVALUE(_xlfn.TEXTBEFORE(RL_iter30!C10, "%")))/100-_xlfn.SINGLE(_xlfn.NUMBERVALUE(_xlfn.TEXTBEFORE(BC_initial_8000!C10, "%")))/100 -> 0.081 | J25: =_xlfn.SINGLE(_xlfn.NUMBERVALUE(_xlfn.TEXTBEFORE(RL_iter30!D10, "%")))/100-_xlfn.SINGLE(_xlfn.NUMBERVALUE(_xlfn.TEXTBEFORE(BC_initial_8000!D10, "%")))/100 -> 0.185 | K25: =_xlfn.SINGLE(_xlfn.NUMBERVALUE(_xlfn.TEXTBEFORE(RL_iter30!E10, "%")))/100-_xlfn.SINGLE(_xlfn.NUMBERVALUE(_xlfn.TEXTBEFORE(BC_initial_8000!E10, "%")))/100 -> 0.195
A26: White Weenie | B26: =_xlfn.SINGLE(_xlfn.NUMBERVALUE(_xlfn.TEXTBEFORE(RL_iter30!B11, "%")))/100-_xlfn.SINGLE(_xlfn.NUMBERVALUE(_xlfn.TEXTBEFORE(HvH_40000!B11, "%")))/100 -> 0.067 | C26: =_xlfn.SINGLE(_xlfn.NUMBERVALUE(_xlfn.TEXTBEFORE(RL_iter30!C11, "%")))/100-_xlfn.SINGLE(_xlfn.NUMBERVALUE(_xlfn.TEXTBEFORE(HvH_40000!C11, "%")))/100 -> -0.004 | D26: =_xlfn.SINGLE(_xlfn.NUMBERVALUE(_xlfn.TEXTBEFORE(RL_iter30!D11, "%")))/100-_xlfn.SINGLE(_xlfn.NUMBERVALUE(_xlfn.TEXTBEFORE(HvH_40000!D11, "%")))/100 -> 0.044 | E26: =_xlfn.SINGLE(_xlfn.NUMBERVALUE(_xlfn.TEXTBEFORE(RL_iter30!E11, "%")))/100-50/100 -> 0.006 | G26: White Weenie | H26: =_xlfn.SINGLE(_xlfn.NUMBERVALUE(_xlfn.TEXTBEFORE(RL_iter30!B11, "%")))/100-_xlfn.SINGLE(_xlfn.NUMBERVALUE(_xlfn.TEXTBEFORE(BC_initial_8000!B11, "%")))/100 -> 0.09 | I26: =_xlfn.SINGLE(_xlfn.NUMBERVALUE(_xlfn.TEXTBEFORE(RL_iter30!C11, "%")))/100-_xlfn.SINGLE(_xlfn.NUMBERVALUE(_xlfn.TEXTBEFORE(BC_initial_8000!C11, "%")))/100 -> 0.063 | J26: =_xlfn.SINGLE(_xlfn.NUMBERVALUE(_xlfn.TEXTBEFORE(RL_iter30!D11, "%")))/100-_xlfn.SINGLE(_xlfn.NUMBERVALUE(_xlfn.TEXTBEFORE(BC_initial_8000!D11, "%")))/100 -> 0.07 | K26: =_xlfn.SINGLE(_xlfn.NUMBERVALUE(_xlfn.TEXTBEFORE(RL_iter30!E11, "%")))/100-_xlfn.SINGLE(_xlfn.NUMBERVALUE(_xlfn.TEXTBEFORE(BC_initial_8000!E11, "%")))/100 -> 0.136
A28: RL_iter40 - HvH_40000 | G28: RL_iter40 - BC_initial_8000
A29: Model deck / reference deck | B29: Blue Tempo | C29: Green Stompy | D29: Red Aggro | E29: White Weenie | G29: Model deck / reference deck | H29: Blue Tempo | I29: Green Stompy | J29: Red Aggro | K29: White Weenie
A30: Blue Tempo | B30: =_xlfn.SINGLE(_xlfn.NUMBERVALUE(_xlfn.TEXTBEFORE(RL_iter40!B8, "%")))/100-50/100 -> 0.026 | C30: =_xlfn.SINGLE(_xlfn.NUMBERVALUE(_xlfn.TEXTBEFORE(RL_iter40!C8, "%")))/100-_xlfn.SINGLE(_xlfn.NUMBERVALUE(_xlfn.TEXTBEFORE(HvH_40000!C8, "%")))/100 -> 0.051 | D30: =_xlfn.SINGLE(_xlfn.NUMBERVALUE(_xlfn.TEXTBEFORE(RL_iter40!D8, "%")))/100-_xlfn.SINGLE(_xlfn.NUMBERVALUE(_xlfn.TEXTBEFORE(HvH_40000!D8, "%")))/100 -> -0.017 | E30: =_xlfn.SINGLE(_xlfn.NUMBERVALUE(_xlfn.TEXTBEFORE(RL_iter40!E8, "%")))/100-_xlfn.SINGLE(_xlfn.NUMBERVALUE(_xlfn.TEXTBEFORE(HvH_40000!E8, "%")))/100 -> 0.061 | G30: Blue Tempo | H30: =_xlfn.SINGLE(_xlfn.NUMBERVALUE(_xlfn.TEXTBEFORE(RL_iter40!B8, "%")))/100-_xlfn.SINGLE(_xlfn.NUMBERVALUE(_xlfn.TEXTBEFORE(BC_initial_8000!B8, "%")))/100 -> 0.038 | I30: =_xlfn.SINGLE(_xlfn.NUMBERVALUE(_xlfn.TEXTBEFORE(RL_iter40!C8, "%")))/100-_xlfn.SINGLE(_xlfn.NUMBERVALUE(_xlfn.TEXTBEFORE(BC_initial_8000!C8, "%")))/100 -> 0.064 | J30: =_xlfn.SINGLE(_xlfn.NUMBERVALUE(_xlfn.TEXTBEFORE(RL_iter40!D8, "%")))/100-_xlfn.SINGLE(_xlfn.NUMBERVALUE(_xlfn.TEXTBEFORE(BC_initial_8000!D8, "%")))/100 -> 0.012 | K30: =_xlfn.SINGLE(_xlfn.NUMBERVALUE(_xlfn.TEXTBEFORE(RL_iter40!E8, "%")))/100-_xlfn.SINGLE(_xlfn.NUMBERVALUE(_xlfn.TEXTBEFORE(BC_initial_8000!E8, "%")))/100 -> 0.054
A31: Green Stompy | B31: =_xlfn.SINGLE(_xlfn.NUMBERVALUE(_xlfn.TEXTBEFORE(RL_iter40!B9, "%")))/100-_xlfn.SINGLE(_xlfn.NUMBERVALUE(_xlfn.TEXTBEFORE(HvH_40000!B9, "%")))/100 -> -0.009 | C31: =_xlfn.SINGLE(_xlfn.NUMBERVALUE(_xlfn.TEXTBEFORE(RL_iter40!C9, "%")))/100-50/100 -> -0.014 | D31: =_xlfn.SINGLE(_xlfn.NUMBERVALUE(_xlfn.TEXTBEFORE(RL_iter40!D9, "%")))/100-_xlfn.SINGLE(_xlfn.NUMBERVALUE(_xlfn.TEXTBEFORE(HvH_40000!D9, "%")))/100 -> 0.036 | E31: =_xlfn.SINGLE(_xlfn.NUMBERVALUE(_xlfn.TEXTBEFORE(RL_iter40!E9, "%")))/100-_xlfn.SINGLE(_xlfn.NUMBERVALUE(_xlfn.TEXTBEFORE(HvH_40000!E9, "%")))/100 -> -0.054 | G31: Green Stompy | H31: =_xlfn.SINGLE(_xlfn.NUMBERVALUE(_xlfn.TEXTBEFORE(RL_iter40!B9, "%")))/100-_xlfn.SINGLE(_xlfn.NUMBERVALUE(_xlfn.TEXTBEFORE(BC_initial_8000!B9, "%")))/100 -> 0.033 | I31: =_xlfn.SINGLE(_xlfn.NUMBERVALUE(_xlfn.TEXTBEFORE(RL_iter40!C9, "%")))/100-_xlfn.SINGLE(_xlfn.NUMBERVALUE(_xlfn.TEXTBEFORE(BC_initial_8000!C9, "%")))/100 -> 0.142 | J31: =_xlfn.SINGLE(_xlfn.NUMBERVALUE(_xlfn.TEXTBEFORE(RL_iter40!D9, "%")))/100-_xlfn.SINGLE(_xlfn.NUMBERVALUE(_xlfn.TEXTBEFORE(BC_initial_8000!D9, "%")))/100 -> 0.121 | K31: =_xlfn.SINGLE(_xlfn.NUMBERVALUE(_xlfn.TEXTBEFORE(RL_iter40!E9, "%")))/100-_xlfn.SINGLE(_xlfn.NUMBERVALUE(_xlfn.TEXTBEFORE(BC_initial_8000!E9, "%")))/100 -> 0.102
A32: Red Aggro | B32: =_xlfn.SINGLE(_xlfn.NUMBERVALUE(_xlfn.TEXTBEFORE(RL_iter40!B10, "%")))/100-_xlfn.SINGLE(_xlfn.NUMBERVALUE(_xlfn.TEXTBEFORE(HvH_40000!B10, "%")))/100 -> 0.073 | C32: =_xlfn.SINGLE(_xlfn.NUMBERVALUE(_xlfn.TEXTBEFORE(RL_iter40!C10, "%")))/100-_xlfn.SINGLE(_xlfn.NUMBERVALUE(_xlfn.TEXTBEFORE(HvH_40000!C10, "%")))/100 -> -0.074 | D32: =_xlfn.SINGLE(_xlfn.NUMBERVALUE(_xlfn.TEXTBEFORE(RL_iter40!D10, "%")))/100-50/100 -> -0.112 | E32: =_xlfn.SINGLE(_xlfn.NUMBERVALUE(_xlfn.TEXTBEFORE(RL_iter40!E10, "%")))/100-_xlfn.SINGLE(_xlfn.NUMBERVALUE(_xlfn.TEXTBEFORE(HvH_40000!E10, "%")))/100 -> 0.08 | G32: Red Aggro | H32: =_xlfn.SINGLE(_xlfn.NUMBERVALUE(_xlfn.TEXTBEFORE(RL_iter40!B10, "%")))/100-_xlfn.SINGLE(_xlfn.NUMBERVALUE(_xlfn.TEXTBEFORE(BC_initial_8000!B10, "%")))/100 -> 0.272 | I32: =_xlfn.SINGLE(_xlfn.NUMBERVALUE(_xlfn.TEXTBEFORE(RL_iter40!C10, "%")))/100-_xlfn.SINGLE(_xlfn.NUMBERVALUE(_xlfn.TEXTBEFORE(BC_initial_8000!C10, "%")))/100 -> 0.083 | J32: =_xlfn.SINGLE(_xlfn.NUMBERVALUE(_xlfn.TEXTBEFORE(RL_iter40!D10, "%")))/100-_xlfn.SINGLE(_xlfn.NUMBERVALUE(_xlfn.TEXTBEFORE(BC_initial_8000!D10, "%")))/100 -> 0.221 | K32: =_xlfn.SINGLE(_xlfn.NUMBERVALUE(_xlfn.TEXTBEFORE(RL_iter40!E10, "%")))/100-_xlfn.SINGLE(_xlfn.NUMBERVALUE(_xlfn.TEXTBEFORE(BC_initial_8000!E10, "%")))/100 -> 0.253
A33: White Weenie | B33: =_xlfn.SINGLE(_xlfn.NUMBERVALUE(_xlfn.TEXTBEFORE(RL_iter40!B11, "%")))/100-_xlfn.SINGLE(_xlfn.NUMBERVALUE(_xlfn.TEXTBEFORE(HvH_40000!B11, "%")))/100 -> 0.051 | C33: =_xlfn.SINGLE(_xlfn.NUMBERVALUE(_xlfn.TEXTBEFORE(RL_iter40!C11, "%")))/100-_xlfn.SINGLE(_xlfn.NUMBERVALUE(_xlfn.TEXTBEFORE(HvH_40000!C11, "%")))/100 -> -0.058 | D33: =_xlfn.SINGLE(_xlfn.NUMBERVALUE(_xlfn.TEXTBEFORE(RL_iter40!D11, "%")))/100-_xlfn.SINGLE(_xlfn.NUMBERVALUE(_xlfn.TEXTBEFORE(HvH_40000!D11, "%")))/100 -> 0.06 | E33: =_xlfn.SINGLE(_xlfn.NUMBERVALUE(_xlfn.TEXTBEFORE(RL_iter40!E11, "%")))/100-50/100 -> 0.002 | G33: White Weenie | H33: =_xlfn.SINGLE(_xlfn.NUMBERVALUE(_xlfn.TEXTBEFORE(RL_iter40!B11, "%")))/100-_xlfn.SINGLE(_xlfn.NUMBERVALUE(_xlfn.TEXTBEFORE(BC_initial_8000!B11, "%")))/100 -> 0.074 | I33: =_xlfn.SINGLE(_xlfn.NUMBERVALUE(_xlfn.TEXTBEFORE(RL_iter40!C11, "%")))/100-_xlfn.SINGLE(_xlfn.NUMBERVALUE(_xlfn.TEXTBEFORE(BC_initial_8000!C11, "%")))/100 -> 0.009 | J33: =_xlfn.SINGLE(_xlfn.NUMBERVALUE(_xlfn.TEXTBEFORE(RL_iter40!D11, "%")))/100-_xlfn.SINGLE(_xlfn.NUMBERVALUE(_xlfn.TEXTBEFORE(BC_initial_8000!D11, "%")))/100 -> 0.086 | K33: =_xlfn.SINGLE(_xlfn.NUMBERVALUE(_xlfn.TEXTBEFORE(RL_iter40!E11, "%")))/100-_xlfn.SINGLE(_xlfn.NUMBERVALUE(_xlfn.TEXTBEFORE(BC_initial_8000!E11, "%")))/100 -> 0.132
A35: RL_iter40 - RL_iter30
A36: Model deck / reference deck | B36: Blue Tempo | C36: Green Stompy | D36: Red Aggro | E36: White Weenie
A37: Blue Tempo | B37: =_xlfn.SINGLE(_xlfn.NUMBERVALUE(_xlfn.TEXTBEFORE(RL_iter40!B8, "%")))/100-_xlfn.SINGLE(_xlfn.NUMBERVALUE(_xlfn.TEXTBEFORE(RL_iter30!B8, "%")))/100 -> -0.032 | C37: =_xlfn.SINGLE(_xlfn.NUMBERVALUE(_xlfn.TEXTBEFORE(RL_iter40!C8, "%")))/100-_xlfn.SINGLE(_xlfn.NUMBERVALUE(_xlfn.TEXTBEFORE(RL_iter30!C8, "%")))/100 -> -0.056 | D37: =_xlfn.SINGLE(_xlfn.NUMBERVALUE(_xlfn.TEXTBEFORE(RL_iter40!D8, "%")))/100-_xlfn.SINGLE(_xlfn.NUMBERVALUE(_xlfn.TEXTBEFORE(RL_iter30!D8, "%")))/100 -> -0.038 | E37: =_xlfn.SINGLE(_xlfn.NUMBERVALUE(_xlfn.TEXTBEFORE(RL_iter40!E8, "%")))/100-_xlfn.SINGLE(_xlfn.NUMBERVALUE(_xlfn.TEXTBEFORE(RL_iter30!E8, "%")))/100 -> 0.01
A38: Green Stompy | B38: =_xlfn.SINGLE(_xlfn.NUMBERVALUE(_xlfn.TEXTBEFORE(RL_iter40!B9, "%")))/100-_xlfn.SINGLE(_xlfn.NUMBERVALUE(_xlfn.TEXTBEFORE(RL_iter30!B9, "%")))/100 -> -0.008 | C38: =_xlfn.SINGLE(_xlfn.NUMBERVALUE(_xlfn.TEXTBEFORE(RL_iter40!C9, "%")))/100-_xlfn.SINGLE(_xlfn.NUMBERVALUE(_xlfn.TEXTBEFORE(RL_iter30!C9, "%")))/100 -> -0.008 | D38: =_xlfn.SINGLE(_xlfn.NUMBERVALUE(_xlfn.TEXTBEFORE(RL_iter40!D9, "%")))/100-_xlfn.SINGLE(_xlfn.NUMBERVALUE(_xlfn.TEXTBEFORE(RL_iter30!D9, "%")))/100 -> -0.008 | E38: =_xlfn.SINGLE(_xlfn.NUMBERVALUE(_xlfn.TEXTBEFORE(RL_iter40!E9, "%")))/100-_xlfn.SINGLE(_xlfn.NUMBERVALUE(_xlfn.TEXTBEFORE(RL_iter30!E9, "%")))/100 -> -0.022
A39: Red Aggro | B39: =_xlfn.SINGLE(_xlfn.NUMBERVALUE(_xlfn.TEXTBEFORE(RL_iter40!B10, "%")))/100-_xlfn.SINGLE(_xlfn.NUMBERVALUE(_xlfn.TEXTBEFORE(RL_iter30!B10, "%")))/100 -> 0.044 | C39: =_xlfn.SINGLE(_xlfn.NUMBERVALUE(_xlfn.TEXTBEFORE(RL_iter40!C10, "%")))/100-_xlfn.SINGLE(_xlfn.NUMBERVALUE(_xlfn.TEXTBEFORE(RL_iter30!C10, "%")))/100 -> 0.002 | D39: =_xlfn.SINGLE(_xlfn.NUMBERVALUE(_xlfn.TEXTBEFORE(RL_iter40!D10, "%")))/100-_xlfn.SINGLE(_xlfn.NUMBERVALUE(_xlfn.TEXTBEFORE(RL_iter30!D10, "%")))/100 -> 0.036 | E39: =_xlfn.SINGLE(_xlfn.NUMBERVALUE(_xlfn.TEXTBEFORE(RL_iter40!E10, "%")))/100-_xlfn.SINGLE(_xlfn.NUMBERVALUE(_xlfn.TEXTBEFORE(RL_iter30!E10, "%")))/100 -> 0.058
A40: White Weenie | B40: =_xlfn.SINGLE(_xlfn.NUMBERVALUE(_xlfn.TEXTBEFORE(RL_iter40!B11, "%")))/100-_xlfn.SINGLE(_xlfn.NUMBERVALUE(_xlfn.TEXTBEFORE(RL_iter30!B11, "%")))/100 -> -0.016 | C40: =_xlfn.SINGLE(_xlfn.NUMBERVALUE(_xlfn.TEXTBEFORE(RL_iter40!C11, "%")))/100-_xlfn.SINGLE(_xlfn.NUMBERVALUE(_xlfn.TEXTBEFORE(RL_iter30!C11, "%")))/100 -> -0.054 | D40: =_xlfn.SINGLE(_xlfn.NUMBERVALUE(_xlfn.TEXTBEFORE(RL_iter40!D11, "%")))/100-_xlfn.SINGLE(_xlfn.NUMBERVALUE(_xlfn.TEXTBEFORE(RL_iter30!D11, "%")))/100 -> 0.016 | E40: =_xlfn.SINGLE(_xlfn.NUMBERVALUE(_xlfn.TEXTBEFORE(RL_iter40!E11, "%")))/100-_xlfn.SINGLE(_xlfn.NUMBERVALUE(_xlfn.TEXTBEFORE(RL_iter30!E11, "%")))/100 -> -0.004
A42: Overall model win rates and 95% CIs (formula-driven)
A43: Evaluation | B43: Games | C43: Model wins | D43: Non-decisive | E43: Win rate | F43: CI lower | G43: CI upper | H43: Formatted result
A44: =README!A6 -> HvH_40000 | B44: =README!C6 -> 40000 | C44: =IF(README!D6="","",README!D6) | D44: =README!F6 -> 0 | E44: =IF(C44="","",C44/B44) | F44: =IF(E44="","",(E44+1.96^2/(2*B44)-1.96*SQRT(E44*(1-E44)/B44+1.96^2/(4*B44^2)))/(1+1.96^2/B44)) | G44: =IF(E44="","",(E44+1.96^2/(2*B44)+1.96*SQRT(E44*(1-E44)/B44+1.96^2/(4*B44^2)))/(1+1.96^2/B44)) | H44: No model-versus-heuristic rate
A45: =README!A7 -> BC_initial_8000 | B45: =README!C7 -> 8000 | C45: =IF(README!D7="","",README!D7) -> 3248 | D45: =README!F7 -> 9 | E45: =IF(C45="","",C45/B45) -> 0.406 | F45: =IF(E45="","",(E45+1.96^2/(2*B45)-1.96*SQRT(E45*(1-E45)/B45+1.96^2/(4*B45^2)))/(1+1.96^2/B45)) -> 0.39528624 | G45: =IF(E45="","",(E45+1.96^2/(2*B45)+1.96*SQRT(E45*(1-E45)/B45+1.96^2/(4*B45^2)))/(1+1.96^2/B45)) -> 0.41680399 | H45: =IF(E45="","No model-versus-heuristic rate",TEXT(E45,"0.0%")&" ["&TEXT(F45,"0.0%")&", "&TEXT(G45,"0.0%")&"]") -> 40.6% [39.5%, 41.7%]
...
